<?xml version="1.0" ?>
<robot name="Robot_GA">

<material name="silver">
  <color rgba="0.700 0.700 0.700 1.000"/>
</material>

<link name="base_link">
  <inertial>
    <origin xyz="-0.07682075088882986 0.11061210181185127 0.14272719812799045" rpy="0 0 0"/>
    <mass value="12.322730126500291"/>
    <inertia ixx="0.048666838915268906" iyy="0.04866683891526946" izz="0.09523953557198009" ixy="-1.3183898417423734e-15" iyz="5.551115123125783e-17" ixz="5.551115123125783e-17"/>
  </inertial>
  <visual>
    <origin xyz="0 0 0" rpy="0 0 0"/>
    <geometry>
      <mesh filename="meshes/base_link.stl" scale="0.001 0.001 0.001"/>
    </geometry>
    <material name="silver"/>
    <material/>
  </visual>
  <collision>
    <origin xyz="0 0 0" rpy="0 0 0"/>
    <geometry>
      <mesh filename="meshes/base_link.stl" scale="0.001 0.001 0.001"/>
    </geometry>
  </collision>
</link>

<link name="Link_11111111">
  <inertial>
    <origin xyz="2.4544070235943405e-07 -0.007900865973038823 0.10039460073341469" rpy="0 0 0"/>
    <mass value="47.95173098521581"/>
    <inertia ixx="0.28677254202160807" iyy="0.25542071508189546" izz="0.24079672853407497" ixy="-8.706012355474968e-09" iyz="0.0040681515590308415" ixz="-4.902126149453068e-09"/>
  </inertial>
  <visual>
    <origin xyz="0.076821 -0.110612 -0.159998" rpy="0 0 0"/>
    <geometry>
      <mesh filename="meshes/Link_11111111.stl" scale="0.001 0.001 0.001"/>
    </geometry>
    <material name="silver"/>
    <material/>
  </visual>
  <collision>
    <origin xyz="0.076821 -0.110612 -0.159998" rpy="0 0 0"/>
    <geometry>
      <mesh filename="meshes/Link_11111111.stl" scale="0.001 0.001 0.001"/>
    </geometry>
  </collision>
</link>

<link name="Link_21111111">
  <inertial>
    <origin xyz="2.4272803450520186e-07 -0.0972877109058419 0.45517511911889685" rpy="0 0 0"/>
    <mass value="104.14884085364247"/>
    <inertia ixx="12.08250919008676" iyy="12.024749075241402" izz="0.273022245292601" ixy="-4.5538451898252674e-09" iyz="0.06571989249764698" ixz="5.046451949652919e-07"/>
  </inertial>
  <visual>
    <origin xyz="0.076821 0.009388 -0.27113" rpy="0 0 0"/>
    <geometry>
      <mesh filename="meshes/Link_21111111.stl" scale="0.001 0.001 0.001"/>
    </geometry>
    <material name="silver"/>
    <material/>
  </visual>
  <collision>
    <origin xyz="0.076821 0.009388 -0.27113" rpy="0 0 0"/>
    <geometry>
      <mesh filename="meshes/Link_21111111.stl" scale="0.001 0.001 0.001"/>
    </geometry>
  </collision>
</link>

<link name="Link_31111111">
  <inertial>
    <origin xyz="2.4911116909553943e-07 0.13955146017807843 0.3019425180292534" rpy="0 0 0"/>
    <mass value="101.5958850714573"/>
    <inertia ixx="6.334119311499023" iyy="6.217424963929034" izz="0.3614722230840042" ixy="6.661338147750939e-16" iyz="-0.4738378888982808" ixz="7.105427357601002e-15"/>
  </inertial>
  <visual>
    <origin xyz="0.076821 0.019388 -1.156998" rpy="0 0 0"/>
    <geometry>
      <mesh filename="meshes/Link_31111111.stl" scale="0.001 0.001 0.001"/>
    </geometry>
    <material name="silver"/>
    <material/>
  </visual>
  <collision>
    <origin xyz="0.076821 0.019388 -1.156998" rpy="0 0 0"/>
    <geometry>
      <mesh filename="meshes/Link_31111111.stl" scale="0.001 0.001 0.001"/>
    </geometry>
  </collision>
</link>

<link name="Link_41111111">
  <inertial>
    <origin xyz="-0.008352446235179084 1.0181185400304216e-07 0.0764510114161745" rpy="0 0 0"/>
    <mass value="24.680512045723788"/>
    <inertia ixx="0.07143306242014091" iyy="0.10082953958935548" izz="0.09301813305238804" ixy="1.1102230246251565e-16" iyz="0.0" ixz="0.0017622767706919618"/>
  </inertial>
  <visual>
    <origin xyz="0.076821 -0.135612 -1.916998" rpy="0 0 0"/>
    <geometry>
      <mesh filename="meshes/Link_41111111.stl" scale="0.001 0.001 0.001"/>
    </geometry>
    <material name="silver"/>
    <material/>
  </visual>
  <collision>
    <origin xyz="0.076821 -0.135612 -1.916998" rpy="0 0 0"/>
    <geometry>
      <mesh filename="meshes/Link_41111111.stl" scale="0.001 0.001 0.001"/>
    </geometry>
  </collision>
</link>

<link name="Link_51111111">
  <inertial>
    <origin xyz="0.08489549306491614 -0.029515773666199632 0.08109378386540111" rpy="0 0 0"/>
    <mass value="47.42171634651961"/>
    <inertia ixx="0.6060335471427436" iyy="0.5628125456807709" izz="0.19671759234049702" ixy="0.00811462488078385" iyz="0.15359508425238566" ixz="-0.02229474978649648"/>
  </inertial>
  <visual>
    <origin xyz="-0.003179 -0.135612 -2.001998" rpy="0 0 0"/>
    <geometry>
      <mesh filename="meshes/Link_51111111.stl" scale="0.001 0.001 0.001"/>
    </geometry>
    <material name="silver"/>
    <material/>
  </visual>
  <collision>
    <origin xyz="-0.003179 -0.135612 -2.001998" rpy="0 0 0"/>
    <geometry>
      <mesh filename="meshes/Link_51111111.stl" scale="0.001 0.001 0.001"/>
    </geometry>
  </collision>
</link>

<link name="Link_61111111">
  <inertial>
    <origin xyz="-0.0002009993404699234 -0.053946335073602296 0.14843006663275604" rpy="0 0 0"/>
    <mass value="33.792943335455206"/>
    <inertia ixx="0.45074487374986916" iyy="0.34580875400706645" izz="0.21821310663125332" ixy="-0.0001076917257439719" iyz="0.053143399286648796" ixz="0.000295578924457196"/>
  </inertial>
  <visual>
    <origin xyz="-0.093872 -0.034716 -2.279207" rpy="0 0 0"/>
    <geometry>
      <mesh filename="meshes/Link_61111111.stl" scale="0.001 0.001 0.001"/>
    </geometry>
    <material name="silver"/>
    <material/>
  </visual>
  <collision>
    <origin xyz="-0.093872 -0.034716 -2.279207" rpy="0 0 0"/>
    <geometry>
      <mesh filename="meshes/Link_61111111.stl" scale="0.001 0.001 0.001"/>
    </geometry>
  </collision>
</link>

<link name="Link_71111111">
  <inertial>
    <origin xyz="0.11377398607759472 -0.0009945493521132248 6.190058636734719e-05" rpy="0 0 0"/>
    <mass value="6.9280302782204"/>
    <inertia ixx="0.008202698664653951" iyy="0.02034163642680653" izz="0.02094285570918153" ixy="9.314145401870255e-05" iyz="-0.00023894440176053244" ixz="-0.0001649610630103382"/>
  </inertial>
  <visual>
    <origin xyz="-0.093712 0.063008 -2.540391" rpy="0 0 0"/>
    <geometry>
      <mesh filename="meshes/Link_71111111.stl" scale="0.001 0.001 0.001"/>
    </geometry>
    <material name="silver"/>
    <material/>
  </visual>
  <collision>
    <origin xyz="-0.093712 0.063008 -2.540391" rpy="0 0 0"/>
    <geometry>
      <mesh filename="meshes/Link_71111111.stl" scale="0.001 0.001 0.001"/>
    </geometry>
  </collision>
</link>

<link name="Grper_21">
  <inertial>
    <origin xyz="0.03654290800794985 -0.059222042668440195 -0.021911740027011906" rpy="0 0 0"/>
    <mass value="1.4743017552778996"/>
    <inertia ixx="0.0024979853784792283" iyy="0.0016692314826052268" izz="0.003321923208977562" ixy="0.0014708568572210368" iyz="-0.000652729563968113" ixz="0.0005161674649727388"/>
  </inertial>
  <visual>
    <origin xyz="-0.269855 0.117834 -2.522906" rpy="0 0 0"/>
    <geometry>
      <mesh filename="meshes/Grper_21.stl" scale="0.001 0.001 0.001"/>
    </geometry>
    <material name="silver"/>
    <material/>
  </visual>
  <collision>
    <origin xyz="-0.269855 0.117834 -2.522906" rpy="0 0 0"/>
    <geometry>
      <mesh filename="meshes/Grper_21.stl" scale="0.001 0.001 0.001"/>
    </geometry>
  </collision>
</link>

<link name="Gripper_11">
  <inertial>
    <origin xyz="-0.012595283461049767 0.06741250797329672 0.024892023045834932" rpy="0 0 0"/>
    <mass value="1.4743017552778996"/>
    <inertia ixx="0.0035971009854343095" iyy="0.000695924635421008" izz="0.0031961144492042848" ixy="0.00023593727468170303" iyz="-0.0010026852878826653" ixz="7.92629223428376e-05"/>
  </inertial>
  <visual>
    <origin xyz="-0.269855 0.014467 -2.560528" rpy="0 0 0"/>
    <geometry>
      <mesh filename="meshes/Gripper_11.stl" scale="0.001 0.001 0.001"/>
    </geometry>
    <material name="silver"/>
    <material/>
  </visual>
  <collision>
    <origin xyz="-0.269855 0.014467 -2.560528" rpy="0 0 0"/>
    <geometry>
      <mesh filename="meshes/Gripper_11.stl" scale="0.001 0.001 0.001"/>
    </geometry>
  </collision>
</link>

<joint name="Revolute_58" type="continuous">
  <origin xyz="-0.076821 0.110612 0.159998" rpy="0 0 0"/>
  <parent link="base_link"/>
  <child link="Link_11111111"/>
  <axis xyz="0.0 -0.0 1.0"/>
</joint>
<transmission name="Revolute_58_tran">
  <type>transmission_interface/SimpleTransmission</type>
  <joint name="Revolute_58">
    <hardwareInterface>PositionJointInterface</hardwareInterface>
  </joint>
  <actuator name="Revolute_58_actr">
    <hardwareInterface>PositionJointInterface</hardwareInterface>
    <mechanicalReduction>1</mechanicalReduction>
  </actuator>
</transmission>

<joint name="Revolute_59" type="revolute">
  <origin xyz="0.0 -0.12 0.111132" rpy="0 0 0"/>
  <parent link="Link_11111111"/>
  <child link="Link_21111111"/>
  <axis xyz="0.0 -1.0 -0.0"/>
  <limit upper="1.570796" lower="-1.570796" effort="100" velocity="100"/>
</joint>
<transmission name="Revolute_59_tran">
  <type>transmission_interface/SimpleTransmission</type>
  <joint name="Revolute_59">
    <hardwareInterface>PositionJointInterface</hardwareInterface>
  </joint>
  <actuator name="Revolute_59_actr">
    <hardwareInterface>PositionJointInterface</hardwareInterface>
    <mechanicalReduction>1</mechanicalReduction>
  </actuator>
</transmission>

<joint name="Revolute_60" type="continuous">
  <origin xyz="0.0 -0.01 0.885868" rpy="0 0 0"/>
  <parent link="Link_21111111"/>
  <child link="Link_31111111"/>
  <axis xyz="-0.0 1.0 0.0"/>
</joint>
<transmission name="Revolute_60_tran">
  <type>transmission_interface/SimpleTransmission</type>
  <joint name="Revolute_60">
    <hardwareInterface>PositionJointInterface</hardwareInterface>
  </joint>
  <actuator name="Revolute_60_actr">
    <hardwareInterface>PositionJointInterface</hardwareInterface>
    <mechanicalReduction>1</mechanicalReduction>
  </actuator>
</transmission>

<joint name="Revolute_61" type="continuous">
  <origin xyz="0.0 0.155 0.76" rpy="0 0 0"/>
  <parent link="Link_31111111"/>
  <child link="Link_41111111"/>
  <axis xyz="-0.0 -0.0 1.0"/>
</joint>
<transmission name="Revolute_61_tran">
  <type>transmission_interface/SimpleTransmission</type>
  <joint name="Revolute_61">
    <hardwareInterface>PositionJointInterface</hardwareInterface>
  </joint>
  <actuator name="Revolute_61_actr">
    <hardwareInterface>PositionJointInterface</hardwareInterface>
    <mechanicalReduction>1</mechanicalReduction>
  </actuator>
</transmission>

<joint name="Revolute_62" type="continuous">
  <origin xyz="0.08 0.0 0.085" rpy="0 0 0"/>
  <parent link="Link_41111111"/>
  <child link="Link_51111111"/>
  <axis xyz="1.0 -0.0 0.0"/>
</joint>
<transmission name="Revolute_62_tran">
  <type>transmission_interface/SimpleTransmission</type>
  <joint name="Revolute_62">
    <hardwareInterface>PositionJointInterface</hardwareInterface>
  </joint>
  <actuator name="Revolute_62_actr">
    <hardwareInterface>PositionJointInterface</hardwareInterface>
    <mechanicalReduction>1</mechanicalReduction>
  </actuator>
</transmission>

<joint name="Revolute_63" type="continuous">
  <origin xyz="0.090693 -0.100896 0.277209" rpy="0 0 0"/>
  <parent link="Link_51111111"/>
  <child link="Link_61111111"/>
  <axis xyz="0.0 0.34202 -0.939693"/>
</joint>
<transmission name="Revolute_63_tran">
  <type>transmission_interface/SimpleTransmission</type>
  <joint name="Revolute_63">
    <hardwareInterface>PositionJointInterface</hardwareInterface>
  </joint>
  <actuator name="Revolute_63_actr">
    <hardwareInterface>PositionJointInterface</hardwareInterface>
    <mechanicalReduction>1</mechanicalReduction>
  </actuator>
</transmission>

<joint name="Revolute_64" type="continuous">
  <origin xyz="-0.00016 -0.097724 0.261184" rpy="0 0 0"/>
  <parent link="Link_61111111"/>
  <child link="Link_71111111"/>
  <axis xyz="0.0 -0.939693 -0.34202"/>
</joint>
<transmission name="Revolute_64_tran">
  <type>transmission_interface/SimpleTransmission</type>
  <joint name="Revolute_64">
    <hardwareInterface>PositionJointInterface</hardwareInterface>
  </joint>
  <actuator name="Revolute_64_actr">
    <hardwareInterface>PositionJointInterface</hardwareInterface>
    <mechanicalReduction>1</mechanicalReduction>
  </actuator>
</transmission>

<joint name="Revolute_75" type="continuous">
  <origin xyz="0.176143 -0.054826 -0.017485" rpy="0 0 0"/>
  <parent link="Link_71111111"/>
  <child link="Grper_21"/>
  <axis xyz="-0.0 0.34202 -0.939693"/>
</joint>
<transmission name="Revolute_75_tran">
  <type>transmission_interface/SimpleTransmission</type>
  <joint name="Revolute_75">
    <hardwareInterface>PositionJointInterface</hardwareInterface>
  </joint>
  <actuator name="Revolute_75_actr">
    <hardwareInterface>PositionJointInterface</hardwareInterface>
    <mechanicalReduction>1</mechanicalReduction>
  </actuator>
</transmission>

<joint name="Revolute_76" type="continuous">
  <origin xyz="0.176143 0.048541 0.020137" rpy="0 0 0"/>
  <parent link="Link_71111111"/>
  <child link="Gripper_11"/>
  <axis xyz="-0.0 0.34202 -0.939693"/>
</joint>
<transmission name="Revolute_76_tran">
  <type>transmission_interface/SimpleTransmission</type>
  <joint name="Revolute_76">
    <hardwareInterface>PositionJointInterface</hardwareInterface>
  </joint>
  <actuator name="Revolute_76_actr">
    <hardwareInterface>PositionJointInterface</hardwareInterface>
    <mechanicalReduction>1</mechanicalReduction>
  </actuator>
</transmission>

</robot>
